"""
Comprehensive Error Handling Tests - CI Ready
Tests all error scenarios and edge cases across the application with mocked dependencies
"""

from unittest.mock import AsyncMock, MagicMock, patch
import asyncio
import pytest

pytestmark = pytest.mark.unit


@pytest.mark.unit
class TestDatabaseErrorHandling:
    """Test database error handling scenarios with mocked dependencies"""

    @pytest.mark.asyncio
    async def test_connection_pool_exhausted(self, mock_database):
        """Test handling when connection pool is exhausted"""
        mock_database.get_memory.side_effect = Exception("Pool exhausted")

        with pytest.raises(Exception) as exc_info:
            await mock_database.get_memory("test-id")

        assert "Pool exhausted" in str(exc_info.value)

    @pytest.mark.asyncio
    async def test_connection_timeout(self, mock_database):
        """Test handling of connection timeouts"""
        mock_database.create_memory.side_effect = asyncio.TimeoutError("Connection timeout")

        with pytest.raises(asyncio.TimeoutError):
            await mock_database.create_memory({"title": "test"})

    @pytest.mark.asyncio
    async def test_database_constraint_violation(self, mock_database):
        """Test handling of database constraint violations"""
        mock_database.create_memory.side_effect = ValueError("Constraint violation")

        with pytest.raises(ValueError) as exc_info:
            await mock_database.create_memory({"title": ""})

        assert "Constraint violation" in str(exc_info.value)

    @pytest.mark.asyncio
    async def test_transaction_rollback(self, mock_database):
        """Test transaction rollback on error"""
        mock_database.create_memory.side_effect = Exception("Transaction failed")

        with pytest.raises(Exception) as exc_info:
            await mock_database.create_memory({"title": "test"})

        assert "Transaction failed" in str(exc_info.value)

    @pytest.mark.asyncio
    async def test_database_unavailable(self, mock_database):
        """Test handling when database is completely unavailable"""
        mock_database.initialize.side_effect = ConnectionError("Database unavailable")

        with pytest.raises(ConnectionError):
            await mock_database.initialize()


@pytest.mark.unit
class TestAPIErrorHandling:
    """Test API error handling scenarios"""

    @pytest.mark.asyncio
    async def test_openai_api_rate_limit(self, mock_openai_client):
        """Test handling of OpenAI API rate limits"""
        mock_openai_client.embeddings.create.side_effect = Exception("Rate limit exceeded")

        with pytest.raises(Exception) as exc_info:
            await mock_openai_client.embeddings.create(
                model="text-embedding-ada-002", input="test text"
            )

        assert "Rate limit exceeded" in str(exc_info.value)

    @pytest.mark.asyncio
    async def test_openai_api_timeout(self, mock_openai_client):
        """Test handling of API timeouts"""
        mock_openai_client.embeddings.create.side_effect = asyncio.TimeoutError("API timeout")

        with pytest.raises(asyncio.TimeoutError):
            await mock_openai_client.embeddings.create(
                model="text-embedding-ada-002", input="test text"
            )

    @pytest.mark.asyncio
    async def test_openai_api_malformed_response(self, mock_openai_client):
        """Test handling of malformed API responses"""
        mock_response = MagicMock()
        mock_response.data = None
        mock_openai_client.embeddings.create.return_value = mock_response

        response = await mock_openai_client.embeddings.create(
            model="text-embedding-ada-002", input="test text"
        )

        assert response.data is None


@pytest.mark.unit
class TestRedisErrorHandling:
    """Test Redis error handling scenarios"""

    @pytest.mark.asyncio
    async def test_redis_connection_lost(self, mock_redis):
        """Test handling of lost Redis connections"""
        mock_redis.get.side_effect = ConnectionError("Redis connection lost")

        with pytest.raises(ConnectionError):
            await mock_redis.get("test_key")

    @pytest.mark.asyncio
    async def test_redis_memory_full(self, mock_redis):
        """Test handling when Redis memory is full"""
        mock_redis.set.side_effect = Exception("Redis memory full")

        with pytest.raises(Exception) as exc_info:
            await mock_redis.set("test_key", "test_value")

        assert "Redis memory full" in str(exc_info.value)

    @pytest.mark.asyncio
    async def test_redis_timeout(self, mock_redis):
        """Test handling of Redis operation timeouts"""
        mock_redis.get.side_effect = asyncio.TimeoutError("Redis timeout")

        with pytest.raises(asyncio.TimeoutError):
            await mock_redis.get("test_key")


@pytest.mark.unit
class TestInputValidationErrors:
    """Test input validation error scenarios"""

    def test_pydantic_validation_errors(self):
        """Test Pydantic validation error handling"""
        from pydantic import BaseModel, ValidationError, Field

        class TestModel(BaseModel):
            name: str = Field(..., min_length=1)  # Require non-empty string
            age: int

        with pytest.raises(ValidationError):
            TestModel(name="", age=25)  # Empty name

        with pytest.raises(ValidationError):
            TestModel(name="Test", age="not_a_number")  # Wrong type

    def test_custom_validation_logic(self):
        """Test custom validation logic"""

        def validate_importance_score(score):
            if not isinstance(score, (int, float)):
                raise TypeError("Importance score must be a number")
            if not 0.0 <= score <= 1.0:
                raise ValueError("Importance score must be between 0.0 and 1.0")
            return score

        # Test valid scores
        assert validate_importance_score(0.5) == 0.5

        # Test invalid scores
        with pytest.raises(TypeError):
            validate_importance_score("0.5")

        with pytest.raises(ValueError):
            validate_importance_score(1.1)


@pytest.mark.unit
class TestRecoveryMechanisms:
    """Test error recovery mechanisms"""

    @pytest.mark.asyncio
    async def test_automatic_retry_on_failure(self, mock_database):
        """Test automatic retry mechanism"""
        attempt_count = 0

        async def failing_then_succeeding(memory_id):
            nonlocal attempt_count
            attempt_count += 1
            if attempt_count < 3:
                raise ConnectionError("Temporary failure")
            return {"attempt": attempt_count, "success": True}

        mock_database.get_memory.side_effect = failing_then_succeeding

        # Simulate retry logic
        max_retries = 3
        for attempt in range(max_retries):
            try:
                result = await mock_database.get_memory("test-id")
                assert result["success"] is True
                assert result["attempt"] == 3
                break
            except ConnectionError:
                if attempt == max_retries - 1:
                    pytest.fail("Max retries exceeded")
                await asyncio.sleep(0.01)  # Brief delay

    @pytest.mark.asyncio
    async def test_graceful_degradation(self, mock_database, mock_redis):
        """Test graceful degradation when services fail"""
        # Redis fails, but database still works
        mock_redis.get.side_effect = ConnectionError("Redis unavailable")
        mock_database.get_memory.return_value = {"id": "test", "title": "Test"}

        # Should fall back to database when cache fails
        with pytest.raises(ConnectionError):
            await mock_redis.get("memory:test")

        # Database should still work
        result = await mock_database.get_memory("test")
        assert result["id"] == "test"
